Workbook

Sheet SALDOS POR CUENTA
A1: SALDOS INICIALES Y FINALES POR CUENTA
A2: Valores tomados del primer y último movimiento registrado de los estados de cuenta en bancos.
A4: Banco | B4: Cuenta | C4: Saldo inicial | D4: Saldo final
A5: AGRÍCOLA | B5: 9596 | C5: 76663.7 | D5: 71075.34
A6: CUSCATLÁN | B6: 2509 | C6: 14148.75 | D6: 21941.21
A7: CUSCATLÁN | B7: 4978 | C7: 33171.6 | D7: 28319.18
A8: BAC | B8: 0386 | C8: 9086.82 | D8: 6003.86
A9: BAC | B9: 6715 | C9: 80183.38 | D9: 81910.29
A10: PROMERICA | B10: 0049 | C10: 51799.49 | D10: 33700.51
A11: DAVIVIENDA | B11: 8202 | C11: 38443.89 | D11: 25869.5
A12: DAVIVIENDA | B12: 1962 | C12: 31.71 | D12: 125.63

Sheet ESTADOS CONSOLIDADOS
A1: Banco | B1: Cuenta | C1: Fecha Transacción | D1: Referencia | E1: Descripción / Transacción | F1: Débito / Cargo / Valor - | G1: Crédito / Abono / Valor + | H1: Saldo disponible / Saldo / Balance
A2: BANCO AGRÍCOLA | B2: 9596 | C2: 46235 | D2: 0 | E2: LIQUIDACION POR PAGOS CON NPE | F2: 0 | G2: 38.42 | H2: 76663.7
A3: BANCO AGRÍCOLA | B3: 9596 | C3: 46235 | D3: 8445219661 | E3: TRANSF. FERNANDO JOSE AMAYA LI | F3: 0 | G3: 85.88 | H3: 76749.58
A4: BANCO AGRÍCOLA | B4: 9596 | C4: 46237 | D4: 0 | E4: LIQUIDACION POR PAGOS CON NPE | F4: 0 | G4: 333.35 | H4: 77082.93
A5: BANCO AGRÍCOLA | B5: 9596 | C5: 46238 | D5: 0 | E5: LIQUIDACION POR PAGOS CON NPE | F5: 0 | G5: 1929.79 | H5: 79012.72
A6: BANCO AGRÍCOLA | B6: 9596 | C6: 46239 | D6: 309717 | E6: LIQUIDACION POR PAGOS CON NPE | F6: 0 | G6: 197.75 | H6: 79210.47
A7: BANCO AGRÍCOLA | B7: 9596 | C7: 46240 | D7: 1416029438 | E7: Transfer365 MATUS INTERNATIONA | F7: 0 | G7: 205.15 | H7: 79415.62
A8: BANCO AGRÍCOLA | B8: 9596 | C8: 46240 | D8: 0 | E8: LIQUIDACION POR PAGOS CON NPE | F8: 0 | G8: 417.67 | H8: 79833.29
A9: BANCO AGRÍCOLA | B9: 9596 | C9: 46241 | D9: 0 | E9: LIQUIDACION POR PAGOS CON NPE | F9: 0 | G9: 406.8 | H9: 80240.09
A10: BANCO AGRÍCOLA | B10: 9596 | C10: 46241 | D10: 1416032209 | E10: Transfer365 CAJA DE CREDITO Y | F10: 0 | G10: 211.88 | H10: 80451.97
A11: BANCO AGRÍCOLA | B11: 9596 | C11: 46241 | D11: 1416032272 | E11: Transfer365 CAJA DE CREDITO Y | F11: 0 | G11: 497.2 | H11: 80949.17
A12: BANCO AGRÍCOLA | B12: 9596 | C12: 46244 | D12: 0 | E12: LIQUIDACION POR PAGOS CON NPE | F12: 0 | G12: 542.4 | H12: 81491.57
A13: BANCO AGRÍCOLA | B13: 9596 | C13: 46244 | D13: 231330071 | E13: TRANSF. COMPAÑIA DE ASESORIA Y | F13: 0 | G13: 174.02 | H13: 81665.59
... A48: BANCO CUSCATLÁN | B48: 2509 | C48: 46245 | D48: 85993049 | E48: DEPOSITO NORMAL CUENTA CORRIENTE | F48: 0 | G48: 372.9 | H48: 15315.29
A49: BANCO CUSCATLÁN | B49: 2509 | C49: 13/08/2026 10:18:00 | D49: 761680361 | E49: ABONO TRANSFER365 PAGOS RECIBIDO | F49: 0 | G49: 1.38 | H49: 15689.57
A50: BANCO CUSCATLÁN | B50: 2509 | C50: 46248 | D50: 83542205 | E50: DEPOSITO NORMAL CUENTA CORRIENTE | F50: 0 | G50: 66.67 | H50: 15689.57
A51: BANCO CUSCATLÁN | B51: 2509 | C51: 46251 | D51: 85993137 | E51: DEPOSITO NORMAL CUENTA CORRIENTE | F51: 0 | G51: 21.47 | H51: 15756.24
A52: BANCO CUSCATLÁN | B52: 2509 | C52: 46252 | D52: 789692036 | E52: ABONO UNI-TRANSFERENCIA DE BANCO A BANCO | F52: 0 | G52: 6163.5 | H52: 21941.21
A53: BANCO CUSCATLÁN | B53: 4978 | C53: 46235 | D53: 720107225 | E53: TRANSFERENCIA LOCAL | F53: 0 | G53: 176.16 | H53: 33171.6
A54: BANCO CUSCATLÁN | B54: 4978 | C54: 46235 | D54: 5063 | E54: PAGO DE CHEQUE TRANSFERIDO | F54: 1691.79 | G54: 0 | H54: 31479.81
A55: BANCO CUSCATLÁN | B55: 4978 | C55: 46237 | D55: 723574350 | E55: ABONO PAGO ELECTRONICO DE TERCERO | F55: 0 | G55: 181.93 | H55: 31661.74
A56: BANCO CUSCATLÁN | B56: 4978 | C56: 46237 | D56: 5071 | E56: PAGO DE CHEQUE DE VENTANILLA | F56: 454.71 | G56: 0 | H56: 31207.03
A57: BANCO CUSCATLÁN | B57: 4978 | C57: 46237 | D57: 724167263 | E57: DEPOSITOS A CUENTA | F57: 0 | G57: 327 | H57: 31534.03
A58: BANCO CUSCATLÁN | B58: 4978 | C58: 46238 | D58: 5073 | E58: PAGO DE CHEQUE DE VENTANILLA | F58: 3337.2 | G58: 0 | H58: 28196.83
A59: BANCO CUSCATLÁN | B59: 4978 | C59: 46238 | D59: 5072 | E59: PAGO DE CHEQUE DE VENTANILLA | F59: 3337.2 | G59: 0 | H59: 24859.63
A60: BANCO CUSCATLÁN | B60: 4978 | C60: 46238 | D60: 2078004802 | E60: RECEPCION DE COLECTORES | F60: 0 | G60: 160 | H60: 25019.63
A61: BANCO CUSCATLÁN | B61: 4978 | C61: 46239 | D61: 729624825 | E61: TRANSFERENCIA LOCAL | F61: 0 | G61: 100 | H61: 25119.63
... A128: BAC | B128: 6715 | C128: 46253 | D128: 205401722 | E128: TEF DE:OCEANICA ESCUELA DE BUC | F128: 0 | G128: 61.02 | H128: 81910.29
A129: PROMERICA | B129: 0049 | C129: 46237.006 | D129: 554582578 | E129: Transferencia por cobro de servicios | F129: 0 | G129: 560.48 | H129: 51799.49
A130: PROMERICA | B130: 0049 | C130: 46237.408 | D130: 826478 | E130: PAGO DE CHEQUE COBRADO POR CAMARA | F130: 2373 | G130: 0 | H130: 49426.49
A131: PROMERICA | B131: 0049 | C131: 46238.002 | D131: 554961533 | E131: Transferencia por cobro de servicios | F131: 0 | G131: 57.63 | H131: 49484.12
A132: PROMERICA | B132: 0049 | C132: 46238.464 | D132: 826479 | E132: Pago de Cheques | F132: 81.36 | G132: 0 | H132: 49402.76
A133: PROMERICA | B133: 0049 | C133: 46241.001 | D133: 556005146 | E133: Transferencia por cobro de servicios | F133: 0 | G133: 76.84 | H133: 49479.6
A134: PROMERICA | B134: 0049 | C134: 46241.54 | D134: 826468 | E134: PAGO DE CHEQUE COBRADO POR CAMARA | F134: 384 | G134: 0 | H134: 49095.6
A135: PROMERICA | B135: 0049 | C135: 46244.401 | D135: 45935253 | E135: Deposito en Cuenta Corriente | F135: 0 | G135: 554.83 | H135: 49650.43
A136: PROMERICA | B136: 0049 | C136: 46245.007 | D136: 557403713 | E136: Transferencia por cobro de servicios | F136: 0 | G136: 552.16 | H136: 50202.59
A137: PROMERICA | B137: 0049 | C137: 46246.059 | D137: 557765645 | E137: Transferencia por cobro de servicios | F137: 0 | G137: 56.5 | H137: 50259.09
A138: PROMERICA | B138: 0049 | C138: 46247.007 | D138: 558124083 | E138: Transferencia por cobro de servicios | F138: 0 | G138: 153.68 | H138: 50412.77
A139: PROMERICA | B139: 0049 | C139: 46247.428 | D139: 45935255 | E139: Deposito en Cuenta Corriente | F139: 0 | G139: 366.12 | H139: 50778.89
A140: PROMERICA | B140: 0049 | C140: 46247.43 | D140: 45935256 | E140: Deposito en Cuenta Corriente | F140: 0 | G140: 1161.44 | H140: 51940.33
...

Sheet REPORTE CREDITOS DIARIOS
A1: RESUMEN DIARIO DE CRÉDITOS / ABONOS
A2: Crédito diario = suma de los valores reportados en Crédito / Abono / Valor + de los movimientos de esa fecha. Los movimientos fuente no se alteran; donde no existe valor reportado, la cuenta queda vacía.
A3: BANCO | B3: AGRÍCOLA | C3: CUSCATLÁN | E3: BAC | G3: PROMERICA | H3: DAVIVIENDA
A4: Fecha | B4: 9596 | C4: 2509 | D4: 4978 | E4: 0386 | F4: 6715 | G4: 0049 | H4: 8202 | I4: 1962 | J4: TOTAL CRÉDITOS | K4: CUENTAS CON ABONO
A5: 46235 | B5: 124.3 | D5: 176.16 | E5: 1015.83 | F5: 8400 | J5: 9716.29 | K5: 4
A6: 46236 | J6: 0 | K6: 0
A7: 46237 | B7: 333.35 | D7: 508.93 | F7: 940.8 | G7: 560.48 | J7: 2343.56 | K7: 4
A8: 46238 | B8: 1929.79 | C8: 985.6 | D8: 160 | E8: 827.16 | F8: 211.31 | G8: 57.63 | H8: 124.3 | J8: 4295.79 | K8: 7
A9: 46239 | B9: 197.75 | D9: 100 | E9: 45.2 | F9: 824.9 | H9: 335.61 | J9: 1503.46 | K9: 5
A10: 46240 | B10: 622.82 | J10: 622.82 | K10: 1
A11: 46241 | B11: 1115.88 | C11: 67.8 | D11: 461.98 | E11: 1021.92 | G11: 76.84 | I11: 22.02 | J11: 2766.44 | K11: 6
A12: 46242 | E12: 814.73 | J12: 814.73 | K12: 1
A13: 46243 | J13: 0 | K13: 0
A14: 46244 | B14: 716.42 | C14: 113.14 | D14: 267.26 | F14: 911.91 | G14: 554.83 | H14: 192.1 | I14: 79.89 | J14: 2835.55 | K14: 7
A15: 46245 | B15: 904 | C15: 372.9 | D15: 604.8 | E15: 0 | F15: 225.25 | G15: 552.16 | H15: 30319 | J15: 32978.11 | K15: 6
A16: 46246 | B16: 6110.3 | D16: 729.98 | E16: 640.59 | F16: 281.29 | G16: 56.5 | H16: 544.59 | J16: 8363.25 | K16: 6
A17: 46247 | B17: 604.86 | C17: 1.38 | E17: 169.3 | F17: 564.08 | G17: 1681.24 | H17: 216.96 | J17: 3237.82 | K17: 6
A18: 46248 | B18: 9077.44 | C18: 66.67 | D18: 25.99 | E18: 1893.46 | F18: 0 | G18: 335.61 | H18: 0 | J18: 11399.17 | K18: 5
A19: 46249 | D19: 532.23 | E19: 40.99 | F19: 84.75 | H19: 244.08 | J19: 902.05 | K19: 4
A20: 46250 | B20: 282.5 | E20: 237.34 | J20: 519.84 | K20: 2
A21: 46251 | B21: 387.59 | C21: 21.47 | D21: 793.26 | F21: 637.25 | G21: 966.05 | H21: 728.06 | J21: 3533.68 | K21: 6
A22: 46252 | B22: 1671.29 | C22: 6163.5 | D22: 339 | E22: 307.38 | G22: 310.24 | J22: 8791.41 | K22: 5
A23: 46253 | B23: 371.77 | D23: 56.5 | E23: 2093.02 | F23: 5251.38 | G23: 485.25 | J23: 8257.92 | K23: 5

Sheet TABLERO CREDITOS
A1: TABLERO DIARIO DE CRÉDITOS / ABONOS | X1: Fecha | Y1: Valor
A2: Selecciona fecha inicial, fecha final y cuenta. “TODAS” consolida los créditos; si eliges una cuenta, esa selección tiene prioridad sobre el Banco. | X2: 01/08 | Y2: =B15 -> 9716.29
X3: 02/08 | Y3: =B16 -> 0
A4: FECHA INICIAL | C4: FECHA FINAL | E4: CUENTA | G4: BANCO | X4: 03/08 | Y4: =B17 -> 2343.56
A5: 46235 | C5: 46253 | E5: TODAS | G5: TODOS | X5: 04/08 | Y5: =B18 -> 4295.79
X6: 05/08 | Y6: =B19 -> 1503.46
A7: CRÉDITOS EN RANGO | C7: PROMEDIO DIARIO | E7: MAYOR DÍA | G7: CUENTAS CON ABONO | I7: SALDO DISPONIBLE | X7: 06/08 | Y7: =B20 -> 622.82
A8: =SUM(H15:H22) -> 102881.89 | C8: =IFERROR(AVERAGEIF(H15:H22,">0"),0) -> 12860.236 | E8: =IFERROR(MAX(H15:H22),0) -> 32704.7 | G8: =COUNTIF(H15:H22,">0") -> 8 | I8: =IF($E$5<>"TODAS",SUMIF('SALDOS POR CUENTA'!$B$5:$B$100,$E$5,'SALDOS POR CUENTA'!$D$5:$D$100),IF($G$5<>"TODOS",SUMIF('SALDOS POR CUENTA'!$A$5:$A$100,"*"&SUBSTITUTE(TRIM($G$5),"BANCO ","")&"*",'SALDOS POR CUENTA'!$D$5:$D$100),SUM('SALDOS POR CUENTA'!$D$5:$D$100))) -> 268945.52 | X8: 07/08 | Y8: =B21 -> 2766.44
X9: 08/08 | Y9: =B22 -> 814.73
X10: 09/08 | Y10: =B23 -> 0
X11: 10/08 | Y11: =B24 -> 2835.55
X12: 11/08 | Y12: =B25 -> 32978.11
A13: EVOLUCIÓN DIARIA EN EL RANGO | F13: CRÉDITOS POR CUENTA EN EL RANGO | X13: 12/08 | Y13: =B26 -> 8363.25
A14: Fecha | B14: Crédito seleccionado | C14: Variación diaria | D14: Cuentas con abono | F14: Banco | G14: Cuenta | H14: Crédito en rango | X14: 13/08 | Y14: =B27 -> 3237.82
A15: =IF(AND('REPORTE CREDITOS DIARIOS'!A5>=$A$5,'REPORTE CREDITOS DIARIOS'!A5<=$C$5),'REPORTE CREDITOS DIARIOS'!A5,"") -> 46235 | B15: =IF(A15="",0,IF($E$5<>"TODAS",IFERROR(INDEX('REPORTE CREDITOS DIARIOS'!$B$5:$I$23,MATCH(A15,'REPORTE CREDITOS DIARIOS'!$A$5:$A$23,0),MATCH($E$5,'REPORTE CREDITOS DIARIOS'!$B$4:$I$4,0)),0),IF($G$5="TODOS",IFERROR(SUMIF('REPORTE CREDITOS DIARIOS'!$A$5:$A$23,A15,'REPORTE CREDITOS DIARIOS'!$J$5:$J$23),0),0))) -> 9716.29 | C15: =0 -> 0 | D15: =IF(A15="",0,IF($G$5="TODOS",IFERROR(INDEX('REPORTE CREDITOS DIARIOS'!$K$5:$K$23,MATCH(A15,'REPORTE CREDITOS DIARIOS'!$A$5:$A$23,0)),0),IF(B15>0,1,0))) -> 4 | F15: BANCO AGRÍCOLA | G15: 9596 | H15: =IF(AND(OR($G$5="TODOS",TRIM($G$5)=TRIM(F15)),OR($E$5="TODAS",TEXT($E$5,"0")=TEXT(G15,"0"))),SUMIFS('REPORTE CREDITOS DIARIOS'!$B$5:$B$23,'REPORTE CREDITOS DIARIOS'!$A$5:$A$23,">="&$A$5,'REPORTE CREDITOS DIARIOS'!$A$5:$A$23,"<="&$C$5),0) -> 24450.06 | X15: 14/08 | Y15: =B28 -> 11399.17
A16: =IF(AND('REPORTE CREDITOS DIARIOS'!A6>=$A$5,'REPORTE CREDITOS DIARIOS'!A6<=$C$5),'REPORTE CREDITOS DIARIOS'!A6,"") -> 46236 | B16: =IF(A16="",0,IF($E$5<>"TODAS",IFERROR(INDEX('REPORTE CREDITOS DIARIOS'!$B$5:$I$23,MATCH(A16,'REPORTE CREDITOS DIARIOS'!$A$5:$A$23,0),MATCH($E$5,'REPORTE CREDITOS DIARIOS'!$B$4:$I$4,0)),0),IF($G$5="TODOS",IFERROR(SUMIF('REPORTE CREDITOS DIARIOS'!$A$5:$A$23,A16,'REPORTE CREDITOS DIARIOS'!$J$5:$J$23),0),0))) -> 0 | C16: =B16-B15 -> -9716.29 | D16: =IF(A16="",0,IF($G$5="TODOS",IFERROR(INDEX('REPORTE CREDITOS DIARIOS'!$K$5:$K$23,MATCH(A16,'REPORTE CREDITOS DIARIOS'!$A$5:$A$23,0)),0),IF(B16>0,1,0))) -> 0 | F16: CUSCATLÁN | G16: 2509 | H16: =IF(AND(OR($G$5="TODOS",TRIM($G$5)=TRIM(F16)),OR($E$5="TODAS",TEXT($E$5,"0")=TEXT(G16,"0"))),SUMIFS('REPORTE CREDITOS DIARIOS'!$C$5:$C$23,'REPORTE CREDITOS DIARIOS'!$A$5:$A$23,">="&$A$5,'REPORTE CREDITOS DIARIOS'!$A$5:$A$23,"<="&$C$5),0) -> 7792.46 | X16: 15/08 | Y16: =B29 -> 902.05
A17: =IF(AND('REPORTE CREDITOS DIARIOS'!A7>=$A$5,'REPORTE CREDITOS DIARIOS'!A7<=$C$5),'REPORTE CREDITOS DIARIOS'!A7,"") -> 46237 | B17: =IF(A17="",0,IF($E$5<>"TODAS",IFERROR(INDEX('REPORTE CREDITOS DIARIOS'!$B$5:$I$23,MATCH(A17,'REPORTE CREDITOS DIARIOS'!$A$5:$A$23,0),MATCH($E$5,'REPORTE CREDITOS DIARIOS'!$B$4:$I$4,0)),0),IF($G$5="TODOS",IFERROR(SUMIF('REPORTE CREDITOS DIARIOS'!$A$5:$A$23,A17,'REPORTE CREDITOS DIARIOS'!$J$5:$J$23),0),0))) -> 2343.56 | C17: =B17-B16 -> 2343.56 | D17: =IF(A17="",0,IF($G$5="TODOS",IFERROR(INDEX('REPORTE CREDITOS DIARIOS'!$K$5:$K$23,MATCH(A17,'REPORTE CREDITOS DIARIOS'!$A$5:$A$23,0)),0),IF(B17>0,1,0))) -> 4 | F17: CUSCATLÁN | G17: 4978 | H17: =IF(AND(OR($G$5="TODOS",TRIM($G$5)=TRIM(F17)),OR($E$5="TODAS",TEXT($E$5,"0")=TEXT(G17,"0"))),SUMIFS('REPORTE CREDITOS DIARIOS'!$D$5:$D$23,'REPORTE CREDITOS DIARIOS'!$A$5:$A$23,">="&$A$5,'REPORTE CREDITOS DIARIOS'!$A$5:$A$23,"<="&$C$5),0) -> 4756.09 | X17: 16/08 | Y17: =B30 -> 519.84
A18: =IF(AND('REPORTE CREDITOS DIARIOS'!A8>=$A$5,'REPORTE CREDITOS DIARIOS'!A8<=$C$5),'REPORTE CREDITOS DIARIOS'!A8,"") -> 46238 | B18: =IF(A18="",0,IF($E$5<>"TODAS",IFERROR(INDEX('REPORTE CREDITOS DIARIOS'!$B$5:$I$23,MATCH(A18,'REPORTE CREDITOS DIARIOS'!$A$5:$A$23,0),MATCH($E$5,'REPORTE CREDITOS DIARIOS'!$B$4:$I$4,0)),0),IF($G$5="TODOS",IFERROR(SUMIF('REPORTE CREDITOS DIARIOS'!$A$5:$A$23,A18,'REPORTE CREDITOS DIARIOS'!$J$5:$J$23),0),0))) -> 4295.79 | C18: =B18-B17 -> 1952.23 | D18: =IF(A18="",0,IF($G$5="TODOS",IFERROR(INDEX('REPORTE CREDITOS DIARIOS'!$K$5:$K$23,MATCH(A18,'REPORTE CREDITOS DIARIOS'!$A$5:$A$23,0)),0),IF(B18>0,1,0))) -> 7 | F18: BAC | G18: 0386 | H18: =IF(AND(OR($G$5="TODOS",TRIM($G$5)=TRIM(F18)),OR($E$5="TODAS",TEXT($E$5,"0")=TEXT(G18,"0"))),SUMIFS('REPORTE CREDITOS DIARIOS'!$E$5:$E$23,'REPORTE CREDITOS DIARIOS'!$A$5:$A$23,">="&$A$5,'REPORTE CREDITOS DIARIOS'!$A$5:$A$23,"<="&$C$5),0) -> 9106.92 | X18: 17/08 | Y18: =B31 -> 3533.68
A19: =IF(AND('REPORTE CREDITOS DIARIOS'!A9>=$A$5,'REPORTE CREDITOS DIARIOS'!A9<=$C$5),'REPORTE CREDITOS DIARIOS'!A9,"") -> 46239 | B19: =IF(A19="",0,IF($E$5<>"TODAS",IFERROR(INDEX('REPORTE CREDITOS DIARIOS'!$B$5:$I$23,MATCH(A19,'REPORTE CREDITOS DIARIOS'!$A$5:$A$23,0),MATCH($E$5,'REPORTE CREDITOS DIARIOS'!$B$4:$I$4,0)),0),IF($G$5="TODOS",IFERROR(SUMIF('REPORTE CREDITOS DIARIOS'!$A$5:$A$23,A19,'REPORTE CREDITOS DIARIOS'!$J$5:$J$23),0),0))) -> 1503.46 | C19: =B19-B18 -> -2792.33 | D19: =IF(A19="",0,IF($G$5="TODOS",IFERROR(INDEX('REPORTE CREDITOS DIARIOS'!$K$5:$K$23,MATCH(A19,'REPORTE CREDITOS DIARIOS'!$A$5:$A$23,0)),0),IF(B19>0,1,0))) -> 5 | F19: BAC | G19: 6715 | H19: =IF(AND(OR($G$5="TODOS",TRIM($G$5)=TRIM(F19)),OR($E$5="TODAS",TEXT($E$5,"0")=TEXT(G19,"0"))),SUMIFS('REPORTE CREDITOS DIARIOS'!$F$5:$F$23,'REPORTE CREDITOS DIARIOS'!$A$5:$A$23,">="&$A$5,'REPORTE CREDITOS DIARIOS'!$A$5:$A$23,"<="&$C$5),0) -> 18332.92 | X19: 18/08 | Y19: =B32 -> 8791.41
A20: =IF(AND('REPORTE CREDITOS DIARIOS'!A10>=$A$5,'REPORTE CREDITOS DIARIOS'!A10<=$C$5),'REPORTE CREDITOS DIARIOS'!A10,"") -> 46240 | B20: =IF(A20="",0,IF($E$5<>"TODAS",IFERROR(INDEX('REPORTE CREDITOS DIARIOS'!$B$5:$I$23,MATCH(A20,'REPORTE CREDITOS DIARIOS'!$A$5:$A$23,0),MATCH($E$5,'REPORTE CREDITOS DIARIOS'!$B$4:$I$4,0)),0),IF($G$5="TODOS",IFERROR(SUMIF('REPORTE CREDITOS DIARIOS'!$A$5:$A$23,A20,'REPORTE CREDITOS DIARIOS'!$J$5:$J$23),0),0))) -> 622.82 | C20: =B20-B19 -> -880.64 | D20: =IF(A20="",0,IF($G$5="TODOS",IFERROR(INDEX('REPORTE CREDITOS DIARIOS'!$K$5:$K$23,MATCH(A20,'REPORTE CREDITOS DIARIOS'!$A$5:$A$23,0)),0),IF(B20>0,1,0))) -> 1 | F20: PROMERICA | G20: 0049 | H20: =IF(AND(OR($G$5="TODOS",TRIM($G$5)=TRIM(F20)),OR($E$5="TODAS",TEXT($E$5,"0")=TEXT(G20,"0"))),SUMIFS('REPORTE CREDITOS DIARIOS'!$G$5:$G$23,'REPORTE CREDITOS DIARIOS'!$A$5:$A$23,">="&$A$5,'REPORTE CREDITOS DIARIOS'!$A$5:$A$23,"<="&$C$5),0) -> 5636.83 | X20: 19/08 | Y20: =B33 -> 8257.92
A21: =IF(AND('REPORTE CREDITOS DIARIOS'!A11>=$A$5,'REPORTE CREDITOS DIARIOS'!A11<=$C$5),'REPORTE CREDITOS DIARIOS'!A11,"") -> 46241 | B21: =IF(A21="",0,IF($E$5<>"TODAS",IFERROR(INDEX('REPORTE CREDITOS DIARIOS'!$B$5:$I$23,MATCH(A21,'REPORTE CREDITOS DIARIOS'!$A$5:$A$23,0),MATCH($E$5,'REPORTE CREDITOS DIARIOS'!$B$4:$I$4,0)),0),IF($G$5="TODOS",IFERROR(SUMIF('REPORTE CREDITOS DIARIOS'!$A$5:$A$23,A21,'REPORTE CREDITOS DIARIOS'!$J$5:$J$23),0),0))) -> 2766.44 | C21: =B21-B20 -> 2143.62 | D21: =IF(A21="",0,IF($G$5="TODOS",IFERROR(INDEX('REPORTE CREDITOS DIARIOS'!$K$5:$K$23,MATCH(A21,'REPORTE CREDITOS DIARIOS'!$A$5:$A$23,0)),0),IF(B21>0,1,0))) -> 6 | F21: DAVIVIENDA | G21: 8202 | H21: =IF(AND(OR($G$5="TODOS",TRIM($G$5)=TRIM(F21)),OR($E$5="TODAS",TEXT($E$5,"0")=TEXT(G21,"0"))),SUMIFS('REPORTE CREDITOS DIARIOS'!$H$5:$H$23,'REPORTE CREDITOS DIARIOS'!$A$5:$A$23,">="&$A$5,'REPORTE CREDITOS DIARIOS'!$A$5:$A$23,"<="&$C$5),0) -> 32704.7
A22: =IF(AND('REPORTE CREDITOS DIARIOS'!A12>=$A$5,'REPORTE CREDITOS DIARIOS'!A12<=$C$5),'REPORTE CREDITOS DIARIOS'!A12,"") -> 46242 | B22: =IF(A22="",0,IF($E$5<>"TODAS",IFERROR(INDEX('REPORTE CREDITOS DIARIOS'!$B$5:$I$23,MATCH(A22,'REPORTE CREDITOS DIARIOS'!$A$5:$A$23,0),MATCH($E$5,'REPORTE CREDITOS DIARIOS'!$B$4:$I$4,0)),0),IF($G$5="TODOS",IFERROR(SUMIF('REPORTE CREDITOS DIARIOS'!$A$5:$A$23,A22,'REPORTE CREDITOS DIARIOS'!$J$5:$J$23),0),0))) -> 814.73 | C22: =B22-B21 -> -1951.71 | D22: =IF(A22="",0,IF($G$5="TODOS",IFERROR(INDEX('REPORTE CREDITOS DIARIOS'!$K$5:$K$23,MATCH(A22,'REPORTE CREDITOS DIARIOS'!$A$5:$A$23,0)),0),IF(B22>0,1,0))) -> 1 | F22: DAVIVIENDA | G22: 1962 | H22: =IF(AND(OR($G$5="TODOS",TRIM($G$5)=TRIM(F22)),OR($E$5="TODAS",TEXT($E$5,"0")=TEXT(G22,"0"))),SUMIFS('REPORTE CREDITOS DIARIOS'!$I$5:$I$23,'REPORTE CREDITOS DIARIOS'!$A$5:$A$23,">="&$A$5,'REPORTE CREDITOS DIARIOS'!$A$5:$A$23,"<="&$C$5),0) -> 101.91
A23: =IF(AND('REPORTE CREDITOS DIARIOS'!A13>=$A$5,'REPORTE CREDITOS DIARIOS'!A13<=$C$5),'REPORTE CREDITOS DIARIOS'!A13,"") -> 46243 | B23: =IF(A23="",0,IF($E$5<>"TODAS",IFERROR(INDEX('REPORTE CREDITOS DIARIOS'!$B$5:$I$23,MATCH(A23,'REPORTE CREDITOS DIARIOS'!$A$5:$A$23,0),MATCH($E$5,'REPORTE CREDITOS DIARIOS'!$B$4:$I$4,0)),0),IF($G$5="TODOS",IFERROR(SUMIF('REPORTE CREDITOS DIARIOS'!$A$5:$A$23,A23,'REPORTE CREDITOS DIARIOS'!$J$5:$J$23),0),0))) -> 0 | C23: =B23-B22 -> -814.73 | D23: =IF(A23="",0,IF($G$5="TODOS",IFERROR(INDEX('REPORTE CREDITOS DIARIOS'!$K$5:$K$23,MATCH(A23,'REPORTE CREDITOS DIARIOS'!$A$5:$A$23,0)),0),IF(B23>0,1,0))) -> 0 | F23: Total | H23: =SUM(H15:H22) -> 102881.89
A24: =IF(AND('REPORTE CREDITOS DIARIOS'!A14>=$A$5,'REPORTE CREDITOS DIARIOS'!A14<=$C$5),'REPORTE CREDITOS DIARIOS'!A14,"") -> 46244 | B24: =IF(A24="",0,IF($E$5<>"TODAS",IFERROR(INDEX('REPORTE CREDITOS DIARIOS'!$B$5:$I$23,MATCH(A24,'REPORTE CREDITOS DIARIOS'!$A$5:$A$23,0),MATCH($E$5,'REPORTE CREDITOS DIARIOS'!$B$4:$I$4,0)),0),IF($G$5="TODOS",IFERROR(SUMIF('REPORTE CREDITOS DIARIOS'!$A$5:$A$23,A24,'REPORTE CREDITOS DIARIOS'!$J$5:$J$23),0),0))) -> 2835.55 | C24: =B24-B23 -> 2835.55 | D24: =IF(A24="",0,IF($G$5="TODOS",IFERROR(INDEX('REPORTE CREDITOS DIARIOS'!$K$5:$K$23,MATCH(A24,'REPORTE CREDITOS DIARIOS'!$A$5:$A$23,0)),0),IF(B24>0,1,0))) -> 7
A25: =IF(AND('REPORTE CREDITOS DIARIOS'!A15>=$A$5,'REPORTE CREDITOS DIARIOS'!A15<=$C$5),'REPORTE CREDITOS DIARIOS'!A15,"") -> 46245 | B25: =IF(A25="",0,IF($E$5<>"TODAS",IFERROR(INDEX('REPORTE CREDITOS DIARIOS'!$B$5:$I$23,MATCH(A25,'REPORTE CREDITOS DIARIOS'!$A$5:$A$23,0),MATCH($E$5,'REPORTE CREDITOS DIARIOS'!$B$4:$I$4,0)),0),IF($G$5="TODOS",IFERROR(SUMIF('REPORTE CREDITOS DIARIOS'!$A$5:$A$23,A25,'REPORTE CREDITOS DIARIOS'!$J$5:$J$23),0),0))) -> 32978.11 | C25: =B25-B24 -> 30142.56 | D25: =IF(A25="",0,IF($G$5="TODOS",IFERROR(INDEX('REPORTE CREDITOS DIARIOS'!$K$5:$K$23,MATCH(A25,'REPORTE CREDITOS DIARIOS'!$A$5:$A$23,0)),0),IF(B25>0,1,0))) -> 6
A26: =IF(AND('REPORTE CREDITOS DIARIOS'!A16>=$A$5,'REPORTE CREDITOS DIARIOS'!A16<=$C$5),'REPORTE CREDITOS DIARIOS'!A16,"") -> 46246 | B26: =IF(A26="",0,IF($E$5<>"TODAS",IFERROR(INDEX('REPORTE CREDITOS DIARIOS'!$B$5:$I$23,MATCH(A26,'REPORTE CREDITOS DIARIOS'!$A$5:$A$23,0),MATCH($E$5,'REPORTE CREDITOS DIARIOS'!$B$4:$I$4,0)),0),IF($G$5="TODOS",IFERROR(SUMIF('REPORTE CREDITOS DIARIOS'!$A$5:$A$23,A26,'REPORTE CREDITOS DIARIOS'!$J$5:$J$23),0),0))) -> 8363.25 | C26: =B26-B25 -> -24614.86 | D26: =IF(A26="",0,IF($G$5="TODOS",IFERROR(INDEX('REPORTE CREDITOS DIARIOS'!$K$5:$K$23,MATCH(A26,'REPORTE CREDITOS DIARIOS'!$A$5:$A$23,0)),0),IF(B26>0,1,0))) -> 6
A27: =IF(AND('REPORTE CREDITOS DIARIOS'!A17>=$A$5,'REPORTE CREDITOS DIARIOS'!A17<=$C$5),'REPORTE CREDITOS DIARIOS'!A17,"") -> 46247 | B27: =IF(A27="",0,IF($E$5<>"TODAS",IFERROR(INDEX('REPORTE CREDITOS DIARIOS'!$B$5:$I$23,MATCH(A27,'REPORTE CREDITOS DIARIOS'!$A$5:$A$23,0),MATCH($E$5,'REPORTE CREDITOS DIARIOS'!$B$4:$I$4,0)),0),IF($G$5="TODOS",IFERROR(SUMIF('REPORTE CREDITOS DIARIOS'!$A$5:$A$23,A27,'REPORTE CREDITOS DIARIOS'!$J$5:$J$23),0),0))) -> 3237.82 | C27: =B27-B26 -> -5125.43 | D27: =IF(A27="",0,IF($G$5="TODOS",IFERROR(INDEX('REPORTE CREDITOS DIARIOS'!$K$5:$K$23,MATCH(A27,'REPORTE CREDITOS DIARIOS'!$A$5:$A$23,0)),0),IF(B27>0,1,0))) -> 6
A28: =IF(AND('REPORTE CREDITOS DIARIOS'!A18>=$A$5,'REPORTE CREDITOS DIARIOS'!A18<=$C$5),'REPORTE CREDITOS DIARIOS'!A18,"") -> 46248 | B28: =IF(A28="",0,IF($E$5<>"TODAS",IFERROR(INDEX('REPORTE CREDITOS DIARIOS'!$B$5:$I$23,MATCH(A28,'REPORTE CREDITOS DIARIOS'!$A$5:$A$23,0),MATCH($E$5,'REPORTE CREDITOS DIARIOS'!$B$4:$I$4,0)),0),IF($G$5="TODOS",IFERROR(SUMIF('REPORTE CREDITOS DIARIOS'!$A$5:$A$23,A28,'REPORTE CREDITOS DIARIOS'!$J$5:$J$23),0),0))) -> 11399.17 | C28: =B28-B27 -> 8161.35 | D28: =IF(A28="",0,IF($G$5="TODOS",IFERROR(INDEX('REPORTE CREDITOS DIARIOS'!$K$5:$K$23,MATCH(A28,'REPORTE CREDITOS DIARIOS'!$A$5:$A$23,0)),0),IF(B28>0,1,0))) -> 5
A29: =IF(AND('REPORTE CREDITOS DIARIOS'!A19>=$A$5,'REPORTE CREDITOS DIARIOS'!A19<=$C$5),'REPORTE CREDITOS DIARIOS'!A19,"") -> 46249 | B29: =IF(A29="",0,IF($E$5<>"TODAS",IFERROR(INDEX('REPORTE CREDITOS DIARIOS'!$B$5:$I$23,MATCH(A29,'REPORTE CREDITOS DIARIOS'!$A$5:$A$23,0),MATCH($E$5,'REPORTE CREDITOS DIARIOS'!$B$4:$I$4,0)),0),IF($G$5="TODOS",IFERROR(SUMIF('REPORTE CREDITOS DIARIOS'!$A$5:$A$23,A29,'REPORTE CREDITOS DIARIOS'!$J$5:$J$23),0),0))) -> 902.05 | C29: =B29-B28 -> -10497.12 | D29: =IF(A29="",0,IF($G$5="TODOS",IFERROR(INDEX('REPORTE CREDITOS DIARIOS'!$K$5:$K$23,MATCH(A29,'REPORTE CREDITOS DIARIOS'!$A$5:$A$23,0)),0),IF(B29>0,1,0))) -> 4
A30: =IF(AND('REPORTE CREDITOS DIARIOS'!A20>=$A$5,'REPORTE CREDITOS DIARIOS'!A20<=$C$5),'REPORTE CREDITOS DIARIOS'!A20,"") -> 46250 | B30: =IF(A30="",0,IF($E$5<>"TODAS",IFERROR(INDEX('REPORTE CREDITOS DIARIOS'!$B$5:$I$23,MATCH(A30,'REPORTE CREDITOS DIARIOS'!$A$5:$A$23,0),MATCH($E$5,'REPORTE CREDITOS DIARIOS'!$B$4:$I$4,0)),0),IF($G$5="TODOS",IFERROR(SUMIF('REPORTE CREDITOS DIARIOS'!$A$5:$A$23,A30,'REPORTE CREDITOS DIARIOS'!$J$5:$J$23),0),0))) -> 519.84 | C30: =B30-B29 -> -382.21 | D30: =IF(A30="",0,IF($G$5="TODOS",IFERROR(INDEX('REPORTE CREDITOS DIARIOS'!$K$5:$K$23,MATCH(A30,'REPORTE CREDITOS DIARIOS'!$A$5:$A$23,0)),0),IF(B30>0,1,0))) -> 2
A31: =IF(AND('REPORTE CREDITOS DIARIOS'!A21>=$A$5,'REPORTE CREDITOS DIARIOS'!A21<=$C$5),'REPORTE CREDITOS DIARIOS'!A21,"") -> 46251 | B31: =IF(A31="",0,IF($E$5<>"TODAS",IFERROR(INDEX('REPORTE CREDITOS DIARIOS'!$B$5:$I$23,MATCH(A31,'REPORTE CREDITOS DIARIOS'!$A$5:$A$23,0),MATCH($E$5,'REPORTE CREDITOS DIARIOS'!$B$4:$I$4,0)),0),IF($G$5="TODOS",IFERROR(SUMIF('REPORTE CREDITOS DIARIOS'!$A$5:$A$23,A31,'REPORTE CREDITOS DIARIOS'!$J$5:$J$23),0),0))) -> 3533.68 | C31: =B31-B30 -> 3013.84 | D31: =IF(A31="",0,IF($G$5="TODOS",IFERROR(INDEX('REPORTE CREDITOS DIARIOS'!$K$5:$K$23,MATCH(A31,'REPORTE CREDITOS DIARIOS'!$A$5:$A$23,0)),0),IF(B31>0,1,0))) -> 6
A32: =IF(AND('REPORTE CREDITOS DIARIOS'!A22>=$A$5,'REPORTE CREDITOS DIARIOS'!A22<=$C$5),'REPORTE CREDITOS DIARIOS'!A22,"") -> 46252 | B32: =IF(A32="",0,IF($E$5<>"TODAS",IFERROR(INDEX('REPORTE CREDITOS DIARIOS'!$B$5:$I$23,MATCH(A32,'REPORTE CREDITOS DIARIOS'!$A$5:$A$23,0),MATCH($E$5,'REPORTE CREDITOS DIARIOS'!$B$4:$I$4,0)),0),IF($G$5="TODOS",IFERROR(SUMIF('REPORTE CREDITOS DIARIOS'!$A$5:$A$23,A32,'REPORTE CREDITOS DIARIOS'!$J$5:$J$23),0),0))) -> 8791.41 | C32: =B32-B31 -> 5257.73 | D32: =IF(A32="",0,IF($G$5="TODOS",IFERROR(INDEX('REPORTE CREDITOS DIARIOS'!$K$5:$K$23,MATCH(A32,'REPORTE CREDITOS DIARIOS'!$A$5:$A$23,0)),0),IF(B32>0,1,0))) -> 5
A33: =IF(AND('REPORTE CREDITOS DIARIOS'!A23>=$A$5,'REPORTE CREDITOS DIARIOS'!A23<=$C$5),'REPORTE CREDITOS DIARIOS'!A23,"") -> 46253 | B33: =IF(A33="",0,IF($E$5<>"TODAS",IFERROR(INDEX('REPORTE CREDITOS DIARIOS'!$B$5:$I$23,MATCH(A33,'REPORTE CREDITOS DIARIOS'!$A$5:$A$23,0),MATCH($E$5,'REPORTE CREDITOS DIARIOS'!$B$4:$I$4,0)),0),IF($G$5="TODOS",IFERROR(SUMIF('REPORTE CREDITOS DIARIOS'!$A$5:$A$23,A33,'REPORTE CREDITOS DIARIOS'!$J$5:$J$23),0),0))) -> 8257.92 | C33: =B33-B32 -> -533.49 | D33: =IF(A33="",0,IF($G$5="TODOS",IFERROR(INDEX('REPORTE CREDITOS DIARIOS'!$K$5:$K$23,MATCH(A33,'REPORTE CREDITOS DIARIOS'!$A$5:$A$23,0)),0),IF(B33>0,1,0))) -> 5
A35: Nota: el reporte suma únicamente los valores existentes en Crédito / Abono / Valor +. Los movimientos originales permanecen sin cambios.
